<sdf version="1.7">
  <world name="world">
    <scene>
      <ambient>0.8 0.8 0.8 1.0</ambient>
      <background>0 0 0</background>
      <grid>false</grid>
    </scene>
    <include>
      <uri>model://sun</uri>
    </include>
    <gui>
      <camera name="gui_camera">
        <pose>11.697820433928772 -36.201871243866165 10 0 0.6 1.57</pose>
      </camera>
      <plugin name="toggle_charging" filename="libtoggle_charging.so" />
      <plugin name="toggle_floors" filename="libtoggle_floors.so">
        <floor name="L1" model_name="starbots_complete_L1">
          <model name="door_kitchen" />
          <model name="door_bathroom1" />
          <model name="door_warehouse1" />
          <model name="door_warehouse2" />
          <model name="door_mini_rrl" />
          <model name="door_office" />
          <model name="door_recordings" />
          <model name="door_closet" />
          <model name="door_rrl" />
          <model name="door_cafeteria" />
          <model name="door_bathroom2" />
          <model name="door_servers" />
          <model name="door_entrance" />
        </floor>
      </plugin>
    </gui>
    <model name="door_kitchen">
      <pose>16.080245142462395 -16.25646027308161 0.0 0 0 -1.562457432607192</pose>
      <link name="right">
        <pose>0 0 1.11 0 0 0</pose>
        <visual name="right_visual">
          <geometry>
            <box>
              <size>1.109589746622178 0.03 2.2</size>
            </box>
          </geometry>
          <material>
            <ambient>0.5 0.25 0 0.6</ambient>
            <diffuse>0.5 0.25 0 0.6</diffuse>
          </material>
        </visual>
        <collision name="right_collision">
          <geometry>
            <box>
              <size>1.109589746622178 0.03 2.2</size>
            </box>
          </geometry>
          <surface>
            <contact>
              <collide_bitmask>0x02</collide_bitmask>
            </contact>
          </surface>
        </collision>
        <inertial>
          <mass>50.0</mass>
          <inertia>
            <ixx>20.17041666666667</ixx>
            <iyy>25.296622524204462</iyy>
            <izz>5.133705857537789</izz>
          </inertia>
        </inertial>
      </link>
      <joint name="right_joint" type="revolute">
        <parent>world</parent>
        <child>right</child>
        <axis>
          <xyz>0 0 -1</xyz>
          <limit>
            <lower>0</lower>
            <upper>1.57</upper>
          </limit>
        </axis>
        <pose>0.559794873311089 0 0 0 0 0</pose>
      </joint>
      <plugin name="door" filename="libdoor.so">
        <v_max_door>0.5</v_max_door>
        <a_max_door>0.3</a_max_door>
        <a_nom_door>0.15</a_nom_door>
        <dx_min_door>0.01</dx_min_door>
        <f_max_door>500.0</f_max_door>
        <door name="door_kitchen" type="SwingDoor" left_joint_name="empty_joint" right_joint_name="right_joint" />
      </plugin>
    </model>
    <model name="door_bathroom1">
      <pose>17.428003476694457 -19.630355640118523 0.0 0 0 1.5695099001705253</pose>
      <link name="right">
        <pose>0 0 1.11 0 0 0</pose>
        <visual name="right_visual">
          <geometry>
            <box>
              <size>1.145627315076036 0.03 2.2</size>
            </box>
          </geometry>
          <material>
            <ambient>0.5 0.25 0 0.6</ambient>
            <diffuse>0.5 0.25 0 0.6</diffuse>
          </material>
        </visual>
        <collision name="right_collision">
          <geometry>
            <box>
              <size>1.145627315076036 0.03 2.2</size>
            </box>
          </geometry>
          <surface>
            <contact>
              <collide_bitmask>0x02</collide_bitmask>
            </contact>
          </surface>
        </collision>
        <inertial>
          <mass>50.0</mass>
          <inertia>
            <ixx>20.17041666666667</ixx>
            <iyy>25.635258104368035</iyy>
            <izz>5.472341437701363</izz>
          </inertia>
        </inertial>
      </link>
      <joint name="right_joint" type="revolute">
        <parent>world</parent>
        <child>right</child>
        <axis>
          <xyz>0 0 -1</xyz>
          <limit>
            <lower>0</lower>
            <upper>1.57</upper>
          </limit>
        </axis>
        <pose>0.577813657538018 0 0 0 0 0</pose>
      </joint>
      <plugin name="door" filename="libdoor.so">
        <v_max_door>0.5</v_max_door>
        <a_max_door>0.3</a_max_door>
        <a_nom_door>0.15</a_nom_door>
        <dx_min_door>0.01</dx_min_door>
        <f_max_door>500.0</f_max_door>
        <door name="door_bathroom1" type="SwingDoor" left_joint_name="empty_joint" right_joint_name="right_joint" />
      </plugin>
    </model>
    <model name="door_warehouse1">
      <pose>7.325118281252149 -17.05888332344462 0.0 0 0 1.5707963267948966</pose>
      <link name="right">
        <pose>0 0 1.11 0 0 0</pose>
        <visual name="right_visual">
          <geometry>
            <box>
              <size>1.0544860697012142 0.03 2.2</size>
            </box>
          </geometry>
          <material>
            <ambient>0.5 0.25 0 0.6</ambient>
            <diffuse>0.5 0.25 0 0.6</diffuse>
          </material>
        </visual>
        <collision name="right_collision">
          <geometry>
            <box>
              <size>1.0544860697012142 0.03 2.2</size>
            </box>
          </geometry>
          <surface>
            <contact>
              <collide_bitmask>0x02</collide_bitmask>
            </contact>
          </surface>
        </collision>
        <inertial>
          <mass>50.0</mass>
          <inertia>
            <ixx>20.17041666666667</ixx>
            <iyy>24.799753629974646</iyy>
            <izz>4.6368369633079745</izz>
          </inertia>
        </inertial>
      </link>
      <joint name="right_joint" type="revolute">
        <parent>world</parent>
        <child>right</child>
        <axis>
          <xyz>0 0 -1</xyz>
          <limit>
            <lower>0</lower>
            <upper>1.57</upper>
          </limit>
        </axis>
        <pose>0.5322430348506071 0 0 0 0 0</pose>
      </joint>
      <plugin name="door" filename="libdoor.so">
        <v_max_door>0.5</v_max_door>
        <a_max_door>0.3</a_max_door>
        <a_nom_door>0.15</a_nom_door>
        <dx_min_door>0.01</dx_min_door>
        <f_max_door>500.0</f_max_door>
        <door name="door_warehouse1" type="SwingDoor" left_joint_name="empty_joint" right_joint_name="right_joint" />
      </plugin>
    </model>
    <model name="door_warehouse2">
      <pose>7.365881657643422 -9.8875816241503 0.0 0 0 -1.5939307383721164</pose>
      <link name="right">
        <pose>0 0 1.11 0 0 0</pose>
        <visual name="right_visual">
          <geometry>
            <box>
              <size>1.145935674024048 0.03 2.2</size>
            </box>
          </geometry>
          <material>
            <ambient>0.5 0.25 0 0.6</ambient>
            <diffuse>0.5 0.25 0 0.6</diffuse>
          </material>
        </visual>
        <collision name="right_collision">
          <geometry>
            <box>
              <size>1.145935674024048 0.03 2.2</size>
            </box>
          </geometry>
          <surface>
            <contact>
              <collide_bitmask>0x02</collide_bitmask>
            </contact>
          </surface>
        </collision>
        <inertial>
          <mass>50.0</mass>
          <inertia>
            <ixx>20.17041666666667</ixx>
            <iyy>25.638202370837295</iyy>
            <izz>5.475285704170623</izz>
          </inertia>
        </inertial>
      </link>
      <joint name="right_joint" type="revolute">
        <parent>world</parent>
        <child>right</child>
        <axis>
          <xyz>0 0 -1</xyz>
          <limit>
            <lower>0</lower>
            <upper>1.57</upper>
          </limit>
        </axis>
        <pose>0.577967837012024 0 0 0 0 0</pose>
      </joint>
      <plugin name="door" filename="libdoor.so">
        <v_max_door>0.5</v_max_door>
        <a_max_door>0.3</a_max_door>
        <a_nom_door>0.15</a_nom_door>
        <dx_min_door>0.01</dx_min_door>
        <f_max_door>500.0</f_max_door>
        <door name="door_warehouse2" type="SwingDoor" left_joint_name="empty_joint" right_joint_name="right_joint" />
      </plugin>
    </model>
    <model name="door_mini_rrl">
      <pose>11.262049732117953 -7.104056498998965 0.0 0 0 1.5709644434662853</pose>
      <link name="right">
        <pose>0 0 1.11 0 0 0</pose>
        <visual name="right_visual">
          <geometry>
            <box>
              <size>1.4048548915879961 0.03 2.2</size>
            </box>
          </geometry>
          <material>
            <ambient>0.5 0.25 0 0.6</ambient>
            <diffuse>0.5 0.25 0 0.6</diffuse>
          </material>
        </visual>
        <collision name="right_collision">
          <geometry>
            <box>
              <size>1.4048548915879961 0.03 2.2</size>
            </box>
          </geometry>
          <surface>
            <contact>
              <collide_bitmask>0x02</collide_bitmask>
            </contact>
          </surface>
        </collision>
        <inertial>
          <mass>50.0</mass>
          <inertia>
            <ixx>20.17041666666667</ixx>
            <iyy>28.39007194341134</iyy>
            <izz>8.227155276744668</izz>
          </inertia>
        </inertial>
      </link>
      <joint name="right_joint" type="revolute">
        <parent>world</parent>
        <child>right</child>
        <axis>
          <xyz>0 0 -1</xyz>
          <limit>
            <lower>0</lower>
            <upper>1.57</upper>
          </limit>
        </axis>
        <pose>0.7074274457939981 0 0 0 0 0</pose>
      </joint>
      <plugin name="door" filename="libdoor.so">
        <v_max_door>0.5</v_max_door>
        <a_max_door>0.3</a_max_door>
        <a_nom_door>0.15</a_nom_door>
        <dx_min_door>0.01</dx_min_door>
        <f_max_door>500.0</f_max_door>
        <door name="door_mini_rrl" type="SwingDoor" left_joint_name="empty_joint" right_joint_name="right_joint" />
      </plugin>
    </model>
    <model name="door_office">
      <pose>7.937768141452234 -6.737632100278285 0.0 0 0 1.5431487698929705</pose>
      <link name="right">
        <pose>0 0 1.11 0 0 0</pose>
        <visual name="right_visual">
          <geometry>
            <box>
              <size>1.23763989223551 0.03 2.2</size>
            </box>
          </geometry>
          <material>
            <ambient>0.5 0.25 0 0.6</ambient>
            <diffuse>0.5 0.25 0 0.6</diffuse>
          </material>
        </visual>
        <collision name="right_collision">
          <geometry>
            <box>
              <size>1.23763989223551 0.03 2.2</size>
            </box>
          </geometry>
          <surface>
            <contact>
              <collide_bitmask>0x02</collide_bitmask>
            </contact>
          </surface>
        </collision>
        <inertial>
          <mass>50.0</mass>
          <inertia>
            <ixx>20.17041666666667</ixx>
            <iyy>26.548968761886357</iyy>
            <izz>6.3860520952196875</izz>
          </inertia>
        </inertial>
      </link>
      <joint name="right_joint" type="revolute">
        <parent>world</parent>
        <child>right</child>
        <axis>
          <xyz>0 0 -1</xyz>
          <limit>
            <lower>0</lower>
            <upper>1.57</upper>
          </limit>
        </axis>
        <pose>0.623819946117755 0 0 0 0 0</pose>
      </joint>
      <plugin name="door" filename="libdoor.so">
        <v_max_door>0.5</v_max_door>
        <a_max_door>0.3</a_max_door>
        <a_nom_door>0.15</a_nom_door>
        <dx_min_door>0.01</dx_min_door>
        <f_max_door>500.0</f_max_door>
        <door name="door_office" type="SwingDoor" left_joint_name="empty_joint" right_joint_name="right_joint" />
      </plugin>
    </model>
    <model name="door_recordings">
      <pose>17.571492940198677 -7.8671334262709545 0.0 0 0 -3.123409491376528</pose>
      <link name="right">
        <pose>0 0 1.11 0 0 0</pose>
        <visual name="right_visual">
          <geometry>
            <box>
              <size>1.2818565879323982 0.03 2.2</size>
            </box>
          </geometry>
          <material>
            <ambient>0.5 0.25 0 0.6</ambient>
            <diffuse>0.5 0.25 0 0.6</diffuse>
          </material>
        </visual>
        <collision name="right_collision">
          <geometry>
            <box>
              <size>1.2818565879323982 0.03 2.2</size>
            </box>
          </geometry>
          <surface>
            <contact>
              <collide_bitmask>0x02</collide_bitmask>
            </contact>
          </surface>
        </collision>
        <inertial>
          <mass>50.0</mass>
          <inertia>
            <ixx>20.17041666666667</ixx>
            <iyy>27.013151300107047</iyy>
            <izz>6.850234633440376</izz>
          </inertia>
        </inertial>
      </link>
      <joint name="right_joint" type="revolute">
        <parent>world</parent>
        <child>right</child>
        <axis>
          <xyz>0 0 -1</xyz>
          <limit>
            <lower>0</lower>
            <upper>1.57</upper>
          </limit>
        </axis>
        <pose>0.6459282939661991 0 0 0 0 0</pose>
      </joint>
      <plugin name="door" filename="libdoor.so">
        <v_max_door>0.5</v_max_door>
        <a_max_door>0.3</a_max_door>
        <a_nom_door>0.15</a_nom_door>
        <dx_min_door>0.01</dx_min_door>
        <f_max_door>500.0</f_max_door>
        <door name="door_recordings" type="SwingDoor" left_joint_name="empty_joint" right_joint_name="right_joint" />
      </plugin>
    </model>
    <model name="door_closet">
      <pose>2.567656634711677 -19.15182947860628 0.0 0 0 3.141165260570925</pose>
      <link name="right">
        <pose>0 0 1.11 0 0 0</pose>
        <visual name="right_visual">
          <geometry>
            <box>
              <size>1.3813464334366092 0.03 2.2</size>
            </box>
          </geometry>
          <material>
            <ambient>0.5 0.25 0 0.6</ambient>
            <diffuse>0.5 0.25 0 0.6</diffuse>
          </material>
        </visual>
        <collision name="right_collision">
          <geometry>
            <box>
              <size>1.3813464334366092 0.03 2.2</size>
            </box>
          </geometry>
          <surface>
            <contact>
              <collide_bitmask>0x02</collide_bitmask>
            </contact>
          </surface>
        </collision>
        <inertial>
          <mass>50.0</mass>
          <inertia>
            <ixx>20.17041666666667</ixx>
            <iyy>28.117158204866843</iyy>
            <izz>7.95424153820017</izz>
          </inertia>
        </inertial>
      </link>
      <joint name="right_joint" type="revolute">
        <parent>world</parent>
        <child>right</child>
        <axis>
          <xyz>0 0 -1</xyz>
          <limit>
            <lower>0</lower>
            <upper>1.57</upper>
          </limit>
        </axis>
        <pose>0.6956732167183046 0 0 0 0 0</pose>
      </joint>
      <plugin name="door" filename="libdoor.so">
        <v_max_door>0.5</v_max_door>
        <a_max_door>0.3</a_max_door>
        <a_nom_door>0.15</a_nom_door>
        <dx_min_door>0.01</dx_min_door>
        <f_max_door>500.0</f_max_door>
        <door name="door_closet" type="SwingDoor" left_joint_name="empty_joint" right_joint_name="right_joint" />
      </plugin>
    </model>
    <model name="door_rrl">
      <pose>12.727222051301975 -10.716377478932754 0.0 0 0 1.5616494156602039</pose>
      <link name="right">
        <pose>0 0 1.11 0 0 0</pose>
        <visual name="right_visual">
          <geometry>
            <box>
              <size>1.1623851166268635 0.03 2.2</size>
            </box>
          </geometry>
          <material>
            <ambient>0.5 0.25 0 0.6</ambient>
            <diffuse>0.5 0.25 0 0.6</diffuse>
          </material>
        </visual>
        <collision name="right_collision">
          <geometry>
            <box>
              <size>1.1623851166268635 0.03 2.2</size>
            </box>
          </geometry>
          <surface>
            <contact>
              <collide_bitmask>0x02</collide_bitmask>
            </contact>
          </surface>
        </collision>
        <inertial>
          <mass>50.0</mass>
          <inertia>
            <ixx>20.17041666666667</ixx>
            <iyy>25.796413163981867</iyy>
            <izz>5.633496497315196</izz>
          </inertia>
        </inertial>
      </link>
      <joint name="right_joint" type="revolute">
        <parent>world</parent>
        <child>right</child>
        <axis>
          <xyz>0 0 -1</xyz>
          <limit>
            <lower>0</lower>
            <upper>1.57</upper>
          </limit>
        </axis>
        <pose>0.5861925583134318 0 0 0 0 0</pose>
      </joint>
      <plugin name="door" filename="libdoor.so">
        <v_max_door>0.5</v_max_door>
        <a_max_door>0.3</a_max_door>
        <a_nom_door>0.15</a_nom_door>
        <dx_min_door>0.01</dx_min_door>
        <f_max_door>500.0</f_max_door>
        <door name="door_rrl" type="SwingDoor" left_joint_name="empty_joint" right_joint_name="right_joint" />
      </plugin>
    </model>
    <model name="door_cafeteria">
      <pose>13.459129316830579 -13.296819125933453 0.0 0 0 0.00034506554875947566</pose>
      <link name="right">
        <pose>0 0 1.11 0 0 0</pose>
        <visual name="right_visual">
          <geometry>
            <box>
              <size>1.5409707459290378 0.03 2.2</size>
            </box>
          </geometry>
          <material>
            <ambient>0.5 0.25 0 0.6</ambient>
            <diffuse>0.5 0.25 0 0.6</diffuse>
          </material>
        </visual>
        <collision name="right_collision">
          <geometry>
            <box>
              <size>1.5409707459290378 0.03 2.2</size>
            </box>
          </geometry>
          <surface>
            <contact>
              <collide_bitmask>0x02</collide_bitmask>
            </contact>
          </surface>
        </collision>
        <inertial>
          <mass>50.0</mass>
          <inertia>
            <ixx>20.17041666666667</ixx>
            <iyy>30.060795165871237</iyy>
            <izz>9.897878499204564</izz>
          </inertia>
        </inertial>
      </link>
      <joint name="right_joint" type="revolute">
        <parent>world</parent>
        <child>right</child>
        <axis>
          <xyz>0 0 -1</xyz>
          <limit>
            <lower>0</lower>
            <upper>1.57</upper>
          </limit>
        </axis>
        <pose>0.7754853729645189 0 0 0 0 0</pose>
      </joint>
      <plugin name="door" filename="libdoor.so">
        <v_max_door>0.5</v_max_door>
        <a_max_door>0.3</a_max_door>
        <a_nom_door>0.15</a_nom_door>
        <dx_min_door>0.01</dx_min_door>
        <f_max_door>500.0</f_max_door>
        <door name="door_cafeteria" type="SwingDoor" left_joint_name="empty_joint" right_joint_name="right_joint" />
      </plugin>
    </model>
    <model name="door_bathroom2">
      <pose>4.527856701036794 -19.8008224706388 0.0 0 0 -1.5707963267948966</pose>
      <link name="right">
        <pose>0 0 1.11 0 0 0</pose>
        <visual name="right_visual">
          <geometry>
            <box>
              <size>1.2545269131443122 0.03 2.2</size>
            </box>
          </geometry>
          <material>
            <ambient>0.5 0.25 0 0.6</ambient>
            <diffuse>0.5 0.25 0 0.6</diffuse>
          </material>
        </visual>
        <collision name="right_collision">
          <geometry>
            <box>
              <size>1.2545269131443122 0.03 2.2</size>
            </box>
          </geometry>
          <surface>
            <contact>
              <collide_bitmask>0x02</collide_bitmask>
            </contact>
          </surface>
        </collision>
        <inertial>
          <mass>50.0</mass>
          <inertia>
            <ixx>20.17041666666667</ixx>
            <iyy>26.72432406584749</iyy>
            <izz>6.561407399180819</izz>
          </inertia>
        </inertial>
      </link>
      <joint name="right_joint" type="revolute">
        <parent>world</parent>
        <child>right</child>
        <axis>
          <xyz>0 0 -1</xyz>
          <limit>
            <lower>0</lower>
            <upper>1.57</upper>
          </limit>
        </axis>
        <pose>0.6322634565721561 0 0 0 0 0</pose>
      </joint>
      <plugin name="door" filename="libdoor.so">
        <v_max_door>0.5</v_max_door>
        <a_max_door>0.3</a_max_door>
        <a_nom_door>0.15</a_nom_door>
        <dx_min_door>0.01</dx_min_door>
        <f_max_door>500.0</f_max_door>
        <door name="door_bathroom2" type="SwingDoor" left_joint_name="empty_joint" right_joint_name="right_joint" />
      </plugin>
    </model>
    <model name="door_servers">
      <pose>14.277994487649003 -10.834891569593305 0.0 0 0 -1.589951878239416</pose>
      <link name="right">
        <pose>0 0 1.11 0 0 0</pose>
        <visual name="right_visual">
          <geometry>
            <box>
              <size>1.2142160836735563 0.03 2.2</size>
            </box>
          </geometry>
          <material>
            <ambient>0.5 0.25 0 0.6</ambient>
            <diffuse>0.5 0.25 0 0.6</diffuse>
          </material>
        </visual>
        <collision name="right_collision">
          <geometry>
            <box>
              <size>1.2142160836735563 0.03 2.2</size>
            </box>
          </geometry>
          <surface>
            <contact>
              <collide_bitmask>0x02</collide_bitmask>
            </contact>
          </surface>
        </collision>
        <inertial>
          <mass>50.0</mass>
          <inertia>
            <ixx>20.17041666666667</ixx>
            <iyy>26.30966957438146</iyy>
            <izz>6.146752907714786</izz>
          </inertia>
        </inertial>
      </link>
      <joint name="right_joint" type="revolute">
        <parent>world</parent>
        <child>right</child>
        <axis>
          <xyz>0 0 -1</xyz>
          <limit>
            <lower>0</lower>
            <upper>1.57</upper>
          </limit>
        </axis>
        <pose>0.6121080418367781 0 0 0 0 0</pose>
      </joint>
      <plugin name="door" filename="libdoor.so">
        <v_max_door>0.5</v_max_door>
        <a_max_door>0.3</a_max_door>
        <a_nom_door>0.15</a_nom_door>
        <dx_min_door>0.01</dx_min_door>
        <f_max_door>500.0</f_max_door>
        <door name="door_servers" type="SwingDoor" left_joint_name="empty_joint" right_joint_name="right_joint" />
      </plugin>
    </model>
    <model name="door_entrance">
      <pose>13.026440893176261 -19.214922027623263 0.0 0 0 0.0</pose>
      <link name="right">
        <pose>0 0 1.11 0 0 0</pose>
        <visual name="right_visual">
          <geometry>
            <box>
              <size>1.2890365354624291 0.03 2.2</size>
            </box>
          </geometry>
          <material>
            <ambient>0.5 0.25 0 0.6</ambient>
            <diffuse>0.5 0.25 0 0.6</diffuse>
          </material>
        </visual>
        <collision name="right_collision">
          <geometry>
            <box>
              <size>1.2890365354624291 0.03 2.2</size>
            </box>
          </geometry>
          <surface>
            <contact>
              <collide_bitmask>0x02</collide_bitmask>
            </contact>
          </surface>
        </collision>
        <inertial>
          <mass>50.0</mass>
          <inertia>
            <ixx>20.17041666666667</ixx>
            <iyy>27.090063290654097</iyy>
            <izz>6.927146623987427</izz>
          </inertia>
        </inertial>
      </link>
      <joint name="right_joint" type="revolute">
        <parent>world</parent>
        <child>right</child>
        <axis>
          <xyz>0 0 -1</xyz>
          <limit>
            <lower>0</lower>
            <upper>1.57</upper>
          </limit>
        </axis>
        <pose>0.6495182677312146 0 0 0 0 0</pose>
      </joint>
      <plugin name="door" filename="libdoor.so">
        <v_max_door>0.5</v_max_door>
        <a_max_door>0.3</a_max_door>
        <a_nom_door>0.15</a_nom_door>
        <dx_min_door>0.01</dx_min_door>
        <f_max_door>500.0</f_max_door>
        <door name="door_entrance" type="SwingDoor" left_joint_name="empty_joint" right_joint_name="right_joint" />
      </plugin>
    </model>
    <include>
      <name>starbots_complete_L1</name>
      <uri>model://starbots_complete_L1</uri>
      <pose>0 0 0.0 0 0 0</pose>
    </include>
    <rmf_charger_waypoints name="charger_waypoints">
      <rmf_vertex name="cleaner_charging_station" x="18.981144609116733" y="-14.123057978258101" level="L1" />
    </rmf_charger_waypoints>
  </world>
</sdf>
